2025-07-27 09:16:26,983 - telegram.ext - ERROR - Network Retry Loop (Bootstrap delete Webhook): Failed run number 0 of 0. Aborting.
Traceback (most recent call last):
  File "/home/conqueror/PycharmProjects/PythonProject/.venv/lib/python3.13/site-packages/httpcore/_async/connection.py", line 78, in handle_async_request
    stream = await self._connect(request)
             ^^^^^^^^^^^^^^^^^^^^^^^^^^^^
  File "/home/conqueror/PycharmProjects/PythonProject/.venv/lib/python3.13/site-packages/httpcore/_async/connection.py", line 156, in _connect
    stream = await stream.start_tls(**kwargs)
             ^^^^^^^^^^^^^^^^^^^^^^^^^^^^^^^^
RuntimeError: coroutine ignored GeneratorExit

During handling of the above exception, another exception occurred:

Traceback (most recent call last):
  File "/home/conqueror/PycharmProjects/PythonProject/.venv/lib/python3.13/site-packages/httpcore/_async/connection_pool.py", line 236, in handle_async_request
    response = await connection.handle_async_request(
               ^^^^^^^^^^^^^^^^^^^^^^^^^^^^^^^^^^^^^^
        pool_request.request
        ^^^^^^^^^^^^^^^^^^^^
    )
    ^
  File "/home/conqueror/PycharmProjects/PythonProject/.venv/lib/python3.13/site-packages/httpcore/_async/connection.py", line 101, in handle_async_request
    raise exc
  File "/home/conqueror/PycharmProjects/PythonProject/.venv/lib/python3.13/site-packages/httpcore/_async/connection.py", line 76, in handle_async_request
    async with self._request_lock:
               ^^^^^^^^^^^^^^^^^^
  File "/home/conqueror/PycharmProjects/PythonProject/.venv/lib/python3.13/site-packages/httpcore/_synchronization.py", line 90, in __aexit__
    self._anyio_lock.release()
    ~~~~~~~~~~~~~~~~~~~~~~~~^^
  File "/home/conqueror/PycharmProjects/PythonProject/.venv/lib/python3.13/site-packages/anyio/_backends/_asyncio.py", line 1838, in release
    if self._owner_task != current_task():
                           ~~~~~~~~~~~~^^
RuntimeError: no running event loop

During handling of the above exception, another exception occurred:

Traceback (most recent call last):
  File "/home/conqueror/PycharmProjects/PythonProject/.venv/lib/python3.13/site-packages/telegram/request/_baserequest.py", line 304, in _request_wrapper
    code, payload = await self.do_request(
                    ^^^^^^^^^^^^^^^^^^^^^^
    ...<7 lines>...
    )
    ^
  File "/home/conqueror/PycharmProjects/PythonProject/.venv/lib/python3.13/site-packages/telegram/request/_httpxrequest.py", line 273, in do_request
    res = await self._client.request(
          ^^^^^^^^^^^^^^^^^^^^^^^^^^^
    ...<6 lines>...
    )
    ^
  File "/home/conqueror/PycharmProjects/PythonProject/.venv/lib/python3.13/site-packages/httpx/_client.py", line 1540, in request
    return await self.send(request, auth=auth, follow_redirects=follow_redirects)
           ^^^^^^^^^^^^^^^^^^^^^^^^^^^^^^^^^^^^^^^^^^^^^^^^^^^^^^^^^^^^^^^^^^^^^^
  File "/home/conqueror/PycharmProjects/PythonProject/.venv/lib/python3.13/site-packages/httpx/_client.py", line 1629, in send
    response = await self._send_handling_auth(
               ^^^^^^^^^^^^^^^^^^^^^^^^^^^^^^^
    ...<4 lines>...
    )
    ^
  File "/home/conqueror/PycharmProjects/PythonProject/.venv/lib/python3.13/site-packages/httpx/_client.py", line 1657, in _send_handling_auth
    response = await self._send_handling_redirects(
               ^^^^^^^^^^^^^^^^^^^^^^^^^^^^^^^^^^^^
    ...<3 lines>...
    )
    ^
  File "/home/conqueror/PycharmProjects/PythonProject/.venv/lib/python3.13/site-packages/httpx/_client.py", line 1694, in _send_handling_redirects
    response = await self._send_single_request(request)
               ^^^^^^^^^^^^^^^^^^^^^^^^^^^^^^^^^^^^^^^^
  File "/home/conqueror/PycharmProjects/PythonProject/.venv/lib/python3.13/site-packages/httpx/_client.py", line 1730, in _send_single_request
    response = await transport.handle_async_request(request)
               ^^^^^^^^^^^^^^^^^^^^^^^^^^^^^^^^^^^^^^^^^^^^^
  File "/home/conqueror/PycharmProjects/PythonProject/.venv/lib/python3.13/site-packages/httpx/_transports/default.py", line 394, in handle_async_request
    resp = await self._pool.handle_async_request(req)
           ^^^^^^^^^^^^^^^^^^^^^^^^^^^^^^^^^^^^^^^^^^
  File "/home/conqueror/PycharmProjects/PythonProject/.venv/lib/python3.13/site-packages/httpcore/_async/connection_pool.py", line 255, in handle_async_request
    await self._close_connections(closing)
  File "/home/conqueror/PycharmProjects/PythonProject/.venv/lib/python3.13/site-packages/httpcore/_async/connection_pool.py", line 343, in _close_connections
    with AsyncShieldCancellation():
         ~~~~~~~~~~~~~~~~~~~~~~~^^
  File "/home/conqueror/PycharmProjects/PythonProject/.venv/lib/python3.13/site-packages/httpcore/_synchronization.py", line 203, in __init__
    self._backend = current_async_library()
                    ~~~~~~~~~~~~~~~~~~~~~^^
  File "/home/conqueror/PycharmProjects/PythonProject/.venv/lib/python3.13/site-packages/httpcore/_synchronization.py", line 30, in current_async_library
    environment = sniffio.current_async_library()
  File "/home/conqueror/PycharmProjects/PythonProject/.venv/lib/python3.13/site-packages/sniffio/_impl.py", line 93, in current_async_library
    raise AsyncLibraryNotFoundError(
        "unknown async library, or not in async context"
    )
sniffio._impl.AsyncLibraryNotFoundError: unknown async library, or not in async context

The above exception was the direct cause of the following exception:

Traceback (most recent call last):
  File "/home/conqueror/PycharmProjects/PythonProject/.venv/lib/python3.13/site-packages/telegram/ext/_utils/networkloop.py", line 115, in network_retry_loop
    if not await do_action():
           ^^^^^^^^^^^^^^^^^
  File "/home/conqueror/PycharmProjects/PythonProject/.venv/lib/python3.13/site-packages/telegram/ext/_utils/networkloop.py", line 93, in do_action
    return await action_cb()
           ^^^^^^^^^^^^^^^^^
  File "/home/conqueror/PycharmProjects/PythonProject/.venv/lib/python3.13/site-packages/telegram/ext/_updater.py", line 685, in bootstrap_del_webhook
    await self.bot.delete_webhook(drop_pending_updates=drop_pending_updates)
  File "/home/conqueror/PycharmProjects/PythonProject/.venv/lib/python3.13/site-packages/telegram/ext/_extbot.py", line 1480, in delete_webhook
    return await super().delete_webhook(
           ^^^^^^^^^^^^^^^^^^^^^^^^^^^^^
    ...<6 lines>...
    )
    ^
  File "/home/conqueror/PycharmProjects/PythonProject/.venv/lib/python3.13/site-packages/telegram/_bot.py", line 4783, in delete_webhook
    return await self._post(
           ^^^^^^^^^^^^^^^^^
    ...<7 lines>...
    )
    ^
  File "/home/conqueror/PycharmProjects/PythonProject/.venv/lib/python3.13/site-packages/telegram/_bot.py", line 698, in _post
    return await self._do_post(
           ^^^^^^^^^^^^^^^^^^^^
    ...<6 lines>...
    )
    ^
  File "/home/conqueror/PycharmProjects/PythonProject/.venv/lib/python3.13/site-packages/telegram/ext/_extbot.py", line 370, in _do_post
    return await super()._do_post(
           ^^^^^^^^^^^^^^^^^^^^^^^
    ...<6 lines>...
    )
    ^
  File "/home/conqueror/PycharmProjects/PythonProject/.venv/lib/python3.13/site-packages/telegram/_bot.py", line 727, in _do_post
    result = await request.post(
             ^^^^^^^^^^^^^^^^^^^
    ...<6 lines>...
    )
    ^
  File "/home/conqueror/PycharmProjects/PythonProject/.venv/lib/python3.13/site-packages/telegram/request/_baserequest.py", line 197, in post
    result = await self._request_wrapper(
             ^^^^^^^^^^^^^^^^^^^^^^^^^^^^
    ...<7 lines>...
    )
    ^
  File "/home/conqueror/PycharmProjects/PythonProject/.venv/lib/python3.13/site-packages/telegram/request/_baserequest.py", line 316, in _request_wrapper
    raise NetworkError(f"Unknown error in HTTP implementation: {exc!r}") from exc
telegram.error.NetworkError: Unknown error in HTTP implementation: AsyncLibraryNotFoundError('unknown async library, or not in async context')
2025-07-27 09:16:46,042 - telegram.ext.Application - INFO - Application started
2025-07-27 10:50:58,546 - httpx - INFO - HTTP Request: POST https://api.telegram.org/botTELEGRAM_BOT_TOKEN/deleteWebhook "HTTP/1.1 404 Not Found"
2025-07-27 10:50:58,548 - telegram.ext - ERROR - Network Retry Loop (Bootstrap delete Webhook): Invalid token. Aborting retry loop.
Traceback (most recent call last):
  File "/home/conqueror/PycharmProjects/PythonProject/.venv/lib/python3.13/site-packages/telegram/ext/_utils/networkloop.py", line 115, in network_retry_loop
    if not await do_action():
           ^^^^^^^^^^^^^^^^^
  File "/home/conqueror/PycharmProjects/PythonProject/.venv/lib/python3.13/site-packages/telegram/ext/_utils/networkloop.py", line 93, in do_action
    return await action_cb()
           ^^^^^^^^^^^^^^^^^
  File "/home/conqueror/PycharmProjects/PythonProject/.venv/lib/python3.13/site-packages/telegram/ext/_updater.py", line 685, in bootstrap_del_webhook
    await self.bot.delete_webhook(drop_pending_updates=drop_pending_updates)
  File "/home/conqueror/PycharmProjects/PythonProject/.venv/lib/python3.13/site-packages/telegram/ext/_extbot.py", line 1480, in delete_webhook
    return await super().delete_webhook(
           ^^^^^^^^^^^^^^^^^^^^^^^^^^^^^
    ...<6 lines>...
    )
    ^
  File "/home/conqueror/PycharmProjects/PythonProject/.venv/lib/python3.13/site-packages/telegram/_bot.py", line 4783, in delete_webhook
    return await self._post(
           ^^^^^^^^^^^^^^^^^
    ...<7 lines>...
    )
    ^
  File "/home/conqueror/PycharmProjects/PythonProject/.venv/lib/python3.13/site-packages/telegram/_bot.py", line 698, in _post
    return await self._do_post(
           ^^^^^^^^^^^^^^^^^^^^
    ...<6 lines>...
    )
    ^
  File "/home/conqueror/PycharmProjects/PythonProject/.venv/lib/python3.13/site-packages/telegram/ext/_extbot.py", line 370, in _do_post
    return await super()._do_post(
           ^^^^^^^^^^^^^^^^^^^^^^^
    ...<6 lines>...
    )
    ^
  File "/home/conqueror/PycharmProjects/PythonProject/.venv/lib/python3.13/site-packages/telegram/_bot.py", line 727, in _do_post
    result = await request.post(
             ^^^^^^^^^^^^^^^^^^^
    ...<6 lines>...
    )
    ^
  File "/home/conqueror/PycharmProjects/PythonProject/.venv/lib/python3.13/site-packages/telegram/request/_baserequest.py", line 197, in post
    result = await self._request_wrapper(
             ^^^^^^^^^^^^^^^^^^^^^^^^^^^^
    ...<7 lines>...
    )
    ^
  File "/home/conqueror/PycharmProjects/PythonProject/.venv/lib/python3.13/site-packages/telegram/request/_baserequest.py", line 374, in _request_wrapper
    raise exception
telegram.error.InvalidToken: Not Found
2025-07-27 10:52:04,782 - httpx - INFO - HTTP Request: POST https://api.telegram.org/botTOKEN/getMe "HTTP/1.1 404 Not Found"
2025-07-27 10:52:04,783 - telegram.ext - ERROR - Network Retry Loop (Bootstrap Initialize Application): Invalid token. Aborting retry loop.
Traceback (most recent call last):
  File "/home/conqueror/PycharmProjects/PythonProject/.venv/lib/python3.13/site-packages/telegram/_bot.py", line 845, in initialize
    await self.get_me()
  File "/home/conqueror/PycharmProjects/PythonProject/.venv/lib/python3.13/site-packages/telegram/ext/_extbot.py", line 1981, in get_me
    return await super().get_me(
           ^^^^^^^^^^^^^^^^^^^^^
    ...<5 lines>...
    )
    ^
  File "/home/conqueror/PycharmProjects/PythonProject/.venv/lib/python3.13/site-packages/telegram/_bot.py", line 976, in get_me
    result = await self._post(
             ^^^^^^^^^^^^^^^^^
    ...<6 lines>...
    )
    ^
  File "/home/conqueror/PycharmProjects/PythonProject/.venv/lib/python3.13/site-packages/telegram/_bot.py", line 698, in _post
    return await self._do_post(
           ^^^^^^^^^^^^^^^^^^^^
    ...<6 lines>...
    )
    ^
  File "/home/conqueror/PycharmProjects/PythonProject/.venv/lib/python3.13/site-packages/telegram/ext/_extbot.py", line 370, in _do_post
    return await super()._do_post(
           ^^^^^^^^^^^^^^^^^^^^^^^
    ...<6 lines>...
    )
    ^
  File "/home/conqueror/PycharmProjects/PythonProject/.venv/lib/python3.13/site-packages/telegram/_bot.py", line 727, in _do_post
    result = await request.post(
             ^^^^^^^^^^^^^^^^^^^
    ...<6 lines>...
    )
    ^
  File "/home/conqueror/PycharmProjects/PythonProject/.venv/lib/python3.13/site-packages/telegram/request/_baserequest.py", line 197, in post
    result = await self._request_wrapper(
             ^^^^^^^^^^^^^^^^^^^^^^^^^^^^
    ...<7 lines>...
    )
    ^
  File "/home/conqueror/PycharmProjects/PythonProject/.venv/lib/python3.13/site-packages/telegram/request/_baserequest.py", line 374, in _request_wrapper
    raise exception
telegram.error.InvalidToken: Not Found

The above exception was the direct cause of the following exception:

Traceback (most recent call last):
  File "/home/conqueror/PycharmProjects/PythonProject/.venv/lib/python3.13/site-packages/telegram/ext/_utils/networkloop.py", line 115, in network_retry_loop
    if not await do_action():
           ^^^^^^^^^^^^^^^^^
  File "/home/conqueror/PycharmProjects/PythonProject/.venv/lib/python3.13/site-packages/telegram/ext/_utils/networkloop.py", line 93, in do_action
    return await action_cb()
           ^^^^^^^^^^^^^^^^^
  File "/home/conqueror/PycharmProjects/PythonProject/.venv/lib/python3.13/site-packages/telegram/ext/_application.py", line 489, in initialize
    await self.bot.initialize()
  File "/home/conqueror/PycharmProjects/PythonProject/.venv/lib/python3.13/site-packages/telegram/ext/_extbot.py", line 316, in initialize
    await super().initialize()
  File "/home/conqueror/PycharmProjects/PythonProject/.venv/lib/python3.13/site-packages/telegram/_bot.py", line 847, in initialize
    raise InvalidToken(f"The token `{self._token}` was rejected by the server.") from exc
telegram.error.InvalidToken: The token `TOKEN` was rejected by the server.
2025-07-27 10:52:54,445 - httpx - INFO - HTTP Request: POST https://api.telegram.org/botTOKEN/getMe "HTTP/1.1 404 Not Found"
2025-07-27 10:52:54,446 - telegram.ext - ERROR - Network Retry Loop (Bootstrap Initialize Application): Invalid token. Aborting retry loop.
Traceback (most recent call last):
  File "/home/conqueror/PycharmProjects/PythonProject/.venv/lib/python3.13/site-packages/telegram/_bot.py", line 845, in initialize
    await self.get_me()
  File "/home/conqueror/PycharmProjects/PythonProject/.venv/lib/python3.13/site-packages/telegram/ext/_extbot.py", line 1981, in get_me
    return await super().get_me(
           ^^^^^^^^^^^^^^^^^^^^^
    ...<5 lines>...
    )
    ^
  File "/home/conqueror/PycharmProjects/PythonProject/.venv/lib/python3.13/site-packages/telegram/_bot.py", line 976, in get_me
    result = await self._post(
             ^^^^^^^^^^^^^^^^^
    ...<6 lines>...
    )
    ^
  File "/home/conqueror/PycharmProjects/PythonProject/.venv/lib/python3.13/site-packages/telegram/_bot.py", line 698, in _post
    return await self._do_post(
           ^^^^^^^^^^^^^^^^^^^^
    ...<6 lines>...
    )
    ^
  File "/home/conqueror/PycharmProjects/PythonProject/.venv/lib/python3.13/site-packages/telegram/ext/_extbot.py", line 370, in _do_post
    return await super()._do_post(
           ^^^^^^^^^^^^^^^^^^^^^^^
    ...<6 lines>...
    )
    ^
  File "/home/conqueror/PycharmProjects/PythonProject/.venv/lib/python3.13/site-packages/telegram/_bot.py", line 727, in _do_post
    result = await request.post(
             ^^^^^^^^^^^^^^^^^^^
    ...<6 lines>...
    )
    ^
  File "/home/conqueror/PycharmProjects/PythonProject/.venv/lib/python3.13/site-packages/telegram/request/_baserequest.py", line 197, in post
    result = await self._request_wrapper(
             ^^^^^^^^^^^^^^^^^^^^^^^^^^^^
    ...<7 lines>...
    )
    ^
  File "/home/conqueror/PycharmProjects/PythonProject/.venv/lib/python3.13/site-packages/telegram/request/_baserequest.py", line 374, in _request_wrapper
    raise exception
telegram.error.InvalidToken: Not Found

The above exception was the direct cause of the following exception:

Traceback (most recent call last):
  File "/home/conqueror/PycharmProjects/PythonProject/.venv/lib/python3.13/site-packages/telegram/ext/_utils/networkloop.py", line 115, in network_retry_loop
    if not await do_action():
           ^^^^^^^^^^^^^^^^^
  File "/home/conqueror/PycharmProjects/PythonProject/.venv/lib/python3.13/site-packages/telegram/ext/_utils/networkloop.py", line 93, in do_action
    return await action_cb()
           ^^^^^^^^^^^^^^^^^
  File "/home/conqueror/PycharmProjects/PythonProject/.venv/lib/python3.13/site-packages/telegram/ext/_application.py", line 489, in initialize
    await self.bot.initialize()
  File "/home/conqueror/PycharmProjects/PythonProject/.venv/lib/python3.13/site-packages/telegram/ext/_extbot.py", line 316, in initialize
    await super().initialize()
  File "/home/conqueror/PycharmProjects/PythonProject/.venv/lib/python3.13/site-packages/telegram/_bot.py", line 847, in initialize
    raise InvalidToken(f"The token `{self._token}` was rejected by the server.") from exc
telegram.error.InvalidToken: The token `TOKEN` was rejected by the server.
2025-07-27 10:59:00,214 - httpx - INFO - HTTP Request: POST https://api.telegram.org/botTOKEN/getMe "HTTP/1.1 404 Not Found"
2025-07-27 10:59:00,215 - telegram.ext - ERROR - Network Retry Loop (Bootstrap Initialize Application): Invalid token. Aborting retry loop.
Traceback (most recent call last):
  File "/home/conqueror/PycharmProjects/PythonProject/.venv/lib/python3.13/site-packages/telegram/_bot.py", line 845, in initialize
    await self.get_me()
  File "/home/conqueror/PycharmProjects/PythonProject/.venv/lib/python3.13/site-packages/telegram/ext/_extbot.py", line 1981, in get_me
    return await super().get_me(
           ^^^^^^^^^^^^^^^^^^^^^
    ...<5 lines>...
    )
    ^
  File "/home/conqueror/PycharmProjects/PythonProject/.venv/lib/python3.13/site-packages/telegram/_bot.py", line 976, in get_me
    result = await self._post(
             ^^^^^^^^^^^^^^^^^
    ...<6 lines>...
    )
    ^
  File "/home/conqueror/PycharmProjects/PythonProject/.venv/lib/python3.13/site-packages/telegram/_bot.py", line 698, in _post
    return await self._do_post(
           ^^^^^^^^^^^^^^^^^^^^
    ...<6 lines>...
    )
    ^
  File "/home/conqueror/PycharmProjects/PythonProject/.venv/lib/python3.13/site-packages/telegram/ext/_extbot.py", line 370, in _do_post
    return await super()._do_post(
           ^^^^^^^^^^^^^^^^^^^^^^^
    ...<6 lines>...
    )
    ^
  File "/home/conqueror/PycharmProjects/PythonProject/.venv/lib/python3.13/site-packages/telegram/_bot.py", line 727, in _do_post
    result = await request.post(
             ^^^^^^^^^^^^^^^^^^^
    ...<6 lines>...
    )
    ^
  File "/home/conqueror/PycharmProjects/PythonProject/.venv/lib/python3.13/site-packages/telegram/request/_baserequest.py", line 197, in post
    result = await self._request_wrapper(
             ^^^^^^^^^^^^^^^^^^^^^^^^^^^^
    ...<7 lines>...
    )
    ^
  File "/home/conqueror/PycharmProjects/PythonProject/.venv/lib/python3.13/site-packages/telegram/request/_baserequest.py", line 374, in _request_wrapper
    raise exception
telegram.error.InvalidToken: Not Found

The above exception was the direct cause of the following exception:

Traceback (most recent call last):
  File "/home/conqueror/PycharmProjects/PythonProject/.venv/lib/python3.13/site-packages/telegram/ext/_utils/networkloop.py", line 115, in network_retry_loop
    if not await do_action():
           ^^^^^^^^^^^^^^^^^
  File "/home/conqueror/PycharmProjects/PythonProject/.venv/lib/python3.13/site-packages/telegram/ext/_utils/networkloop.py", line 93, in do_action
    return await action_cb()
           ^^^^^^^^^^^^^^^^^
  File "/home/conqueror/PycharmProjects/PythonProject/.venv/lib/python3.13/site-packages/telegram/ext/_application.py", line 489, in initialize
    await self.bot.initialize()
  File "/home/conqueror/PycharmProjects/PythonProject/.venv/lib/python3.13/site-packages/telegram/ext/_extbot.py", line 316, in initialize
    await super().initialize()
  File "/home/conqueror/PycharmProjects/PythonProject/.venv/lib/python3.13/site-packages/telegram/_bot.py", line 847, in initialize
    raise InvalidToken(f"The token `{self._token}` was rejected by the server.") from exc
telegram.error.InvalidToken: The token `TOKEN` was rejected by the server.
2025-07-27 10:59:37,992 - telegram.ext.Updater - ERROR - Error while calling `get_updates` one more time to mark all fetched updates as read: %s. Suppressing error to ensure graceful shutdown. When polling for updates is restarted, updates may be fetched again. Please adjust timeouts via `ApplicationBuilder` or the parameter `get_updates_request` of `Bot`.
Traceback (most recent call last):
  File "/home/conqueror/PycharmProjects/PythonProject/.venv/lib/python3.13/site-packages/httpx/_transports/default.py", line 101, in map_httpcore_exceptions
    yield
  File "/home/conqueror/PycharmProjects/PythonProject/.venv/lib/python3.13/site-packages/httpx/_transports/default.py", line 394, in handle_async_request
    resp = await self._pool.handle_async_request(req)
           ^^^^^^^^^^^^^^^^^^^^^^^^^^^^^^^^^^^^^^^^^^
  File "/home/conqueror/PycharmProjects/PythonProject/.venv/lib/python3.13/site-packages/httpcore/_async/connection_pool.py", line 256, in handle_async_request
    raise exc from None
  File "/home/conqueror/PycharmProjects/PythonProject/.venv/lib/python3.13/site-packages/httpcore/_async/connection_pool.py", line 236, in handle_async_request
    response = await connection.handle_async_request(
               ^^^^^^^^^^^^^^^^^^^^^^^^^^^^^^^^^^^^^^
        pool_request.request
        ^^^^^^^^^^^^^^^^^^^^
    )
    ^
  File "/home/conqueror/PycharmProjects/PythonProject/.venv/lib/python3.13/site-packages/httpcore/_async/connection.py", line 101, in handle_async_request
    raise exc
  File "/home/conqueror/PycharmProjects/PythonProject/.venv/lib/python3.13/site-packages/httpcore/_async/connection.py", line 78, in handle_async_request
    stream = await self._connect(request)
             ^^^^^^^^^^^^^^^^^^^^^^^^^^^^
  File "/home/conqueror/PycharmProjects/PythonProject/.venv/lib/python3.13/site-packages/httpcore/_async/connection.py", line 124, in _connect
    stream = await self._network_backend.connect_tcp(**kwargs)
             ^^^^^^^^^^^^^^^^^^^^^^^^^^^^^^^^^^^^^^^^^^^^^^^^^
  File "/home/conqueror/PycharmProjects/PythonProject/.venv/lib/python3.13/site-packages/httpcore/_backends/auto.py", line 31, in connect_tcp
    return await self._backend.connect_tcp(
           ^^^^^^^^^^^^^^^^^^^^^^^^^^^^^^^^
    ...<5 lines>...
    )
    ^
  File "/home/conqueror/PycharmProjects/PythonProject/.venv/lib/python3.13/site-packages/httpcore/_backends/anyio.py", line 113, in connect_tcp
    with map_exceptions(exc_map):
         ~~~~~~~~~~~~~~^^^^^^^^^
  File "/usr/lib/python3.13/contextlib.py", line 162, in __exit__
    self.gen.throw(value)
    ~~~~~~~~~~~~~~^^^^^^^
  File "/home/conqueror/PycharmProjects/PythonProject/.venv/lib/python3.13/site-packages/httpcore/_exceptions.py", line 14, in map_exceptions
    raise to_exc(exc) from exc
httpcore.ConnectTimeout

The above exception was the direct cause of the following exception:

Traceback (most recent call last):
  File "/home/conqueror/PycharmProjects/PythonProject/.venv/lib/python3.13/site-packages/telegram/request/_httpxrequest.py", line 273, in do_request
    res = await self._client.request(
          ^^^^^^^^^^^^^^^^^^^^^^^^^^^
    ...<6 lines>...
    )
    ^
  File "/home/conqueror/PycharmProjects/PythonProject/.venv/lib/python3.13/site-packages/httpx/_client.py", line 1540, in request
    return await self.send(request, auth=auth, follow_redirects=follow_redirects)
           ^^^^^^^^^^^^^^^^^^^^^^^^^^^^^^^^^^^^^^^^^^^^^^^^^^^^^^^^^^^^^^^^^^^^^^
  File "/home/conqueror/PycharmProjects/PythonProject/.venv/lib/python3.13/site-packages/httpx/_client.py", line 1629, in send
    response = await self._send_handling_auth(
               ^^^^^^^^^^^^^^^^^^^^^^^^^^^^^^^
    ...<4 lines>...
    )
    ^
  File "/home/conqueror/PycharmProjects/PythonProject/.venv/lib/python3.13/site-packages/httpx/_client.py", line 1657, in _send_handling_auth
    response = await self._send_handling_redirects(
               ^^^^^^^^^^^^^^^^^^^^^^^^^^^^^^^^^^^^
    ...<3 lines>...
    )
    ^
  File "/home/conqueror/PycharmProjects/PythonProject/.venv/lib/python3.13/site-packages/httpx/_client.py", line 1694, in _send_handling_redirects
    response = await self._send_single_request(request)
               ^^^^^^^^^^^^^^^^^^^^^^^^^^^^^^^^^^^^^^^^
  File "/home/conqueror/PycharmProjects/PythonProject/.venv/lib/python3.13/site-packages/httpx/_client.py", line 1730, in _send_single_request
    response = await transport.handle_async_request(request)
               ^^^^^^^^^^^^^^^^^^^^^^^^^^^^^^^^^^^^^^^^^^^^^
  File "/home/conqueror/PycharmProjects/PythonProject/.venv/lib/python3.13/site-packages/httpx/_transports/default.py", line 393, in handle_async_request
    with map_httpcore_exceptions():
         ~~~~~~~~~~~~~~~~~~~~~~~^^
  File "/usr/lib/python3.13/contextlib.py", line 162, in __exit__
    self.gen.throw(value)
    ~~~~~~~~~~~~~~^^^^^^^
  File "/home/conqueror/PycharmProjects/PythonProject/.venv/lib/python3.13/site-packages/httpx/_transports/default.py", line 118, in map_httpcore_exceptions
    raise mapped_exc(message) from exc
httpx.ConnectTimeout

The above exception was the direct cause of the following exception:

Traceback (most recent call last):
  File "/home/conqueror/PycharmProjects/PythonProject/.venv/lib/python3.13/site-packages/telegram/ext/_updater.py", line 399, in _get_updates_cleanup
    await self.bot.get_updates(
    ...<4 lines>...
    )
  File "/home/conqueror/PycharmProjects/PythonProject/.venv/lib/python3.13/site-packages/telegram/ext/_extbot.py", line 670, in get_updates
    updates = await super().get_updates(
              ^^^^^^^^^^^^^^^^^^^^^^^^^^
    ...<9 lines>...
    )
    ^
  File "/home/conqueror/PycharmProjects/PythonProject/.venv/lib/python3.13/site-packages/telegram/_bot.py", line 4611, in get_updates
    await self._post(
    ^^^^^^^^^^^^^^^^^
    ...<7 lines>...
    ),
    ^
  File "/home/conqueror/PycharmProjects/PythonProject/.venv/lib/python3.13/site-packages/telegram/_bot.py", line 698, in _post
    return await self._do_post(
           ^^^^^^^^^^^^^^^^^^^^
    ...<6 lines>...
    )
    ^
  File "/home/conqueror/PycharmProjects/PythonProject/.venv/lib/python3.13/site-packages/telegram/ext/_extbot.py", line 370, in _do_post
    return await super()._do_post(
           ^^^^^^^^^^^^^^^^^^^^^^^
    ...<6 lines>...
    )
    ^
  File "/home/conqueror/PycharmProjects/PythonProject/.venv/lib/python3.13/site-packages/telegram/_bot.py", line 727, in _do_post
    result = await request.post(
             ^^^^^^^^^^^^^^^^^^^
    ...<6 lines>...
    )
    ^
  File "/home/conqueror/PycharmProjects/PythonProject/.venv/lib/python3.13/site-packages/telegram/request/_baserequest.py", line 197, in post
    result = await self._request_wrapper(
             ^^^^^^^^^^^^^^^^^^^^^^^^^^^^
    ...<7 lines>...
    )
    ^
  File "/home/conqueror/PycharmProjects/PythonProject/.venv/lib/python3.13/site-packages/telegram/request/_baserequest.py", line 304, in _request_wrapper
    code, payload = await self.do_request(
                    ^^^^^^^^^^^^^^^^^^^^^^
    ...<7 lines>...
    )
    ^
  File "/home/conqueror/PycharmProjects/PythonProject/.venv/lib/python3.13/site-packages/telegram/request/_httpxrequest.py", line 290, in do_request
    raise TimedOut from err
telegram.error.TimedOut: Timed out
2025-07-27 11:06:18,689 - telegram.ext.Application - INFO - Application started
2025-07-27 11:07:28,730 - root - INFO - User (7317705516) in private: 'helllo'
2025-07-27 11:07:28,730 - root - INFO - Bot response: {response}
2025-07-27 11:07:33,736 - root - ERROR - Update Update(message=Message(channel_chat_created=False, chat=Chat(first_name='Onyi', id=7317705516, last_name='Kachi 🦴🐾', type=<ChatType.PRIVATE>, username='GeorgeTero'), date=datetime.datetime(2025, 7, 27, 15, 7, 28, tzinfo=datetime.timezone.utc), delete_chat_photo=False, from_user=User(first_name='Onyi', id=7317705516, is_bot=False, language_code='en', last_name='Kachi 🦴🐾', username='GeorgeTero'), group_chat_created=False, message_id=93, supergroup_chat_created=False, text='helllo'), update_id=678871824) caused error Timed out
2025-07-27 11:07:34,162 - root - INFO - User (7317705516) in private: 'hello'
2025-07-27 11:07:34,163 - root - INFO - Bot response: {response}
2025-07-27 11:07:39,166 - root - ERROR - Update Update(message=Message(channel_chat_created=False, chat=Chat(first_name='Onyi', id=7317705516, last_name='Kachi 🦴🐾', type=<ChatType.PRIVATE>, username='GeorgeTero'), date=datetime.datetime(2025, 7, 27, 15, 7, 34, tzinfo=datetime.timezone.utc), delete_chat_photo=False, from_user=User(first_name='Onyi', id=7317705516, is_bot=False, language_code='en', last_name='Kachi 🦴🐾', username='GeorgeTero'), group_chat_created=False, message_id=94, supergroup_chat_created=False, text='hello'), update_id=678871825) caused error Timed out
2025-07-27 11:07:50,839 - telegram.ext.Updater - ERROR - Error while calling `get_updates` one more time to mark all fetched updates as read: %s. Suppressing error to ensure graceful shutdown. When polling for updates is restarted, updates may be fetched again. Please adjust timeouts via `ApplicationBuilder` or the parameter `get_updates_request` of `Bot`.
Traceback (most recent call last):
  File "/home/conqueror/PycharmProjects/PythonProject/.venv/lib/python3.13/site-packages/httpx/_transports/default.py", line 101, in map_httpcore_exceptions
    yield
  File "/home/conqueror/PycharmProjects/PythonProject/.venv/lib/python3.13/site-packages/httpx/_transports/default.py", line 394, in handle_async_request
    resp = await self._pool.handle_async_request(req)
           ^^^^^^^^^^^^^^^^^^^^^^^^^^^^^^^^^^^^^^^^^^
  File "/home/conqueror/PycharmProjects/PythonProject/.venv/lib/python3.13/site-packages/httpcore/_async/connection_pool.py", line 256, in handle_async_request
    raise exc from None
  File "/home/conqueror/PycharmProjects/PythonProject/.venv/lib/python3.13/site-packages/httpcore/_async/connection_pool.py", line 236, in handle_async_request
    response = await connection.handle_async_request(
               ^^^^^^^^^^^^^^^^^^^^^^^^^^^^^^^^^^^^^^
        pool_request.request
        ^^^^^^^^^^^^^^^^^^^^
    )
    ^
  File "/home/conqueror/PycharmProjects/PythonProject/.venv/lib/python3.13/site-packages/httpcore/_async/connection.py", line 101, in handle_async_request
    raise exc
  File "/home/conqueror/PycharmProjects/PythonProject/.venv/lib/python3.13/site-packages/httpcore/_async/connection.py", line 78, in handle_async_request
    stream = await self._connect(request)
             ^^^^^^^^^^^^^^^^^^^^^^^^^^^^
  File "/home/conqueror/PycharmProjects/PythonProject/.venv/lib/python3.13/site-packages/httpcore/_async/connection.py", line 124, in _connect
    stream = await self._network_backend.connect_tcp(**kwargs)
             ^^^^^^^^^^^^^^^^^^^^^^^^^^^^^^^^^^^^^^^^^^^^^^^^^
  File "/home/conqueror/PycharmProjects/PythonProject/.venv/lib/python3.13/site-packages/httpcore/_backends/auto.py", line 31, in connect_tcp
    return await self._backend.connect_tcp(
           ^^^^^^^^^^^^^^^^^^^^^^^^^^^^^^^^
    ...<5 lines>...
    )
    ^
  File "/home/conqueror/PycharmProjects/PythonProject/.venv/lib/python3.13/site-packages/httpcore/_backends/anyio.py", line 113, in connect_tcp
    with map_exceptions(exc_map):
         ~~~~~~~~~~~~~~^^^^^^^^^
  File "/usr/lib/python3.13/contextlib.py", line 162, in __exit__
    self.gen.throw(value)
    ~~~~~~~~~~~~~~^^^^^^^
  File "/home/conqueror/PycharmProjects/PythonProject/.venv/lib/python3.13/site-packages/httpcore/_exceptions.py", line 14, in map_exceptions
    raise to_exc(exc) from exc
httpcore.ConnectTimeout

The above exception was the direct cause of the following exception:

Traceback (most recent call last):
  File "/home/conqueror/PycharmProjects/PythonProject/.venv/lib/python3.13/site-packages/telegram/request/_httpxrequest.py", line 273, in do_request
    res = await self._client.request(
          ^^^^^^^^^^^^^^^^^^^^^^^^^^^
    ...<6 lines>...
    )
    ^
  File "/home/conqueror/PycharmProjects/PythonProject/.venv/lib/python3.13/site-packages/httpx/_client.py", line 1540, in request
    return await self.send(request, auth=auth, follow_redirects=follow_redirects)
           ^^^^^^^^^^^^^^^^^^^^^^^^^^^^^^^^^^^^^^^^^^^^^^^^^^^^^^^^^^^^^^^^^^^^^^
  File "/home/conqueror/PycharmProjects/PythonProject/.venv/lib/python3.13/site-packages/httpx/_client.py", line 1629, in send
    response = await self._send_handling_auth(
               ^^^^^^^^^^^^^^^^^^^^^^^^^^^^^^^
    ...<4 lines>...
    )
    ^
  File "/home/conqueror/PycharmProjects/PythonProject/.venv/lib/python3.13/site-packages/httpx/_client.py", line 1657, in _send_handling_auth
    response = await self._send_handling_redirects(
               ^^^^^^^^^^^^^^^^^^^^^^^^^^^^^^^^^^^^
    ...<3 lines>...
    )
    ^
  File "/home/conqueror/PycharmProjects/PythonProject/.venv/lib/python3.13/site-packages/httpx/_client.py", line 1694, in _send_handling_redirects
    response = await self._send_single_request(request)
               ^^^^^^^^^^^^^^^^^^^^^^^^^^^^^^^^^^^^^^^^
  File "/home/conqueror/PycharmProjects/PythonProject/.venv/lib/python3.13/site-packages/httpx/_client.py", line 1730, in _send_single_request
    response = await transport.handle_async_request(request)
               ^^^^^^^^^^^^^^^^^^^^^^^^^^^^^^^^^^^^^^^^^^^^^
  File "/home/conqueror/PycharmProjects/PythonProject/.venv/lib/python3.13/site-packages/httpx/_transports/default.py", line 393, in handle_async_request
    with map_httpcore_exceptions():
         ~~~~~~~~~~~~~~~~~~~~~~~^^
  File "/usr/lib/python3.13/contextlib.py", line 162, in __exit__
    self.gen.throw(value)
    ~~~~~~~~~~~~~~^^^^^^^
  File "/home/conqueror/PycharmProjects/PythonProject/.venv/lib/python3.13/site-packages/httpx/_transports/default.py", line 118, in map_httpcore_exceptions
    raise mapped_exc(message) from exc
httpx.ConnectTimeout

The above exception was the direct cause of the following exception:

Traceback (most recent call last):
  File "/home/conqueror/PycharmProjects/PythonProject/.venv/lib/python3.13/site-packages/telegram/ext/_updater.py", line 399, in _get_updates_cleanup
    await self.bot.get_updates(
    ...<4 lines>...
    )
  File "/home/conqueror/PycharmProjects/PythonProject/.venv/lib/python3.13/site-packages/telegram/ext/_extbot.py", line 670, in get_updates
    updates = await super().get_updates(
              ^^^^^^^^^^^^^^^^^^^^^^^^^^
    ...<9 lines>...
    )
    ^
  File "/home/conqueror/PycharmProjects/PythonProject/.venv/lib/python3.13/site-packages/telegram/_bot.py", line 4611, in get_updates
    await self._post(
    ^^^^^^^^^^^^^^^^^
    ...<7 lines>...
    ),
    ^
  File "/home/conqueror/PycharmProjects/PythonProject/.venv/lib/python3.13/site-packages/telegram/_bot.py", line 698, in _post
    return await self._do_post(
           ^^^^^^^^^^^^^^^^^^^^
    ...<6 lines>...
    )
    ^
  File "/home/conqueror/PycharmProjects/PythonProject/.venv/lib/python3.13/site-packages/telegram/ext/_extbot.py", line 370, in _do_post
    return await super()._do_post(
           ^^^^^^^^^^^^^^^^^^^^^^^
    ...<6 lines>...
    )
    ^
  File "/home/conqueror/PycharmProjects/PythonProject/.venv/lib/python3.13/site-packages/telegram/_bot.py", line 727, in _do_post
    result = await request.post(
             ^^^^^^^^^^^^^^^^^^^
    ...<6 lines>...
    )
    ^
  File "/home/conqueror/PycharmProjects/PythonProject/.venv/lib/python3.13/site-packages/telegram/request/_baserequest.py", line 197, in post
    result = await self._request_wrapper(
             ^^^^^^^^^^^^^^^^^^^^^^^^^^^^
    ...<7 lines>...
    )
    ^
  File "/home/conqueror/PycharmProjects/PythonProject/.venv/lib/python3.13/site-packages/telegram/request/_baserequest.py", line 304, in _request_wrapper
    code, payload = await self.do_request(
                    ^^^^^^^^^^^^^^^^^^^^^^
    ...<7 lines>...
    )
    ^
  File "/home/conqueror/PycharmProjects/PythonProject/.venv/lib/python3.13/site-packages/telegram/request/_httpxrequest.py", line 290, in do_request
    raise TimedOut from err
telegram.error.TimedOut: Timed out
2025-07-27 11:07:50,854 - telegram.ext.Application - INFO - Application is stopping. This might take a moment.
2025-07-27 11:07:50,854 - telegram.ext.Application - INFO - Application.stop() complete
2025-07-27 11:07:52,390 - telegram.ext.Application - INFO - Application started
2025-07-27 11:08:27,917 - root - INFO - User (7317705516) in private: 'hello'
2025-07-27 11:08:27,917 - root - INFO - Bot response: {response}
2025-07-27 11:08:54,636 - telegram.ext.Updater - ERROR - Error while calling `get_updates` one more time to mark all fetched updates as read: %s. Suppressing error to ensure graceful shutdown. When polling for updates is restarted, updates may be fetched again. Please adjust timeouts via `ApplicationBuilder` or the parameter `get_updates_request` of `Bot`.
Traceback (most recent call last):
  File "/home/conqueror/PycharmProjects/PythonProject/.venv/lib/python3.13/site-packages/httpx/_transports/default.py", line 101, in map_httpcore_exceptions
    yield
  File "/home/conqueror/PycharmProjects/PythonProject/.venv/lib/python3.13/site-packages/httpx/_transports/default.py", line 394, in handle_async_request
    resp = await self._pool.handle_async_request(req)
           ^^^^^^^^^^^^^^^^^^^^^^^^^^^^^^^^^^^^^^^^^^
  File "/home/conqueror/PycharmProjects/PythonProject/.venv/lib/python3.13/site-packages/httpcore/_async/connection_pool.py", line 256, in handle_async_request
    raise exc from None
  File "/home/conqueror/PycharmProjects/PythonProject/.venv/lib/python3.13/site-packages/httpcore/_async/connection_pool.py", line 236, in handle_async_request
    response = await connection.handle_async_request(
               ^^^^^^^^^^^^^^^^^^^^^^^^^^^^^^^^^^^^^^
        pool_request.request
        ^^^^^^^^^^^^^^^^^^^^
    )
    ^
  File "/home/conqueror/PycharmProjects/PythonProject/.venv/lib/python3.13/site-packages/httpcore/_async/connection.py", line 101, in handle_async_request
    raise exc
  File "/home/conqueror/PycharmProjects/PythonProject/.venv/lib/python3.13/site-packages/httpcore/_async/connection.py", line 78, in handle_async_request
    stream = await self._connect(request)
             ^^^^^^^^^^^^^^^^^^^^^^^^^^^^
  File "/home/conqueror/PycharmProjects/PythonProject/.venv/lib/python3.13/site-packages/httpcore/_async/connection.py", line 124, in _connect
    stream = await self._network_backend.connect_tcp(**kwargs)
             ^^^^^^^^^^^^^^^^^^^^^^^^^^^^^^^^^^^^^^^^^^^^^^^^^
  File "/home/conqueror/PycharmProjects/PythonProject/.venv/lib/python3.13/site-packages/httpcore/_backends/auto.py", line 31, in connect_tcp
    return await self._backend.connect_tcp(
           ^^^^^^^^^^^^^^^^^^^^^^^^^^^^^^^^
    ...<5 lines>...
    )
    ^
  File "/home/conqueror/PycharmProjects/PythonProject/.venv/lib/python3.13/site-packages/httpcore/_backends/anyio.py", line 113, in connect_tcp
    with map_exceptions(exc_map):
         ~~~~~~~~~~~~~~^^^^^^^^^
  File "/usr/lib/python3.13/contextlib.py", line 162, in __exit__
    self.gen.throw(value)
    ~~~~~~~~~~~~~~^^^^^^^
  File "/home/conqueror/PycharmProjects/PythonProject/.venv/lib/python3.13/site-packages/httpcore/_exceptions.py", line 14, in map_exceptions
    raise to_exc(exc) from exc
httpcore.ConnectTimeout

The above exception was the direct cause of the following exception:

Traceback (most recent call last):
  File "/home/conqueror/PycharmProjects/PythonProject/.venv/lib/python3.13/site-packages/telegram/request/_httpxrequest.py", line 273, in do_request
    res = await self._client.request(
          ^^^^^^^^^^^^^^^^^^^^^^^^^^^
    ...<6 lines>...
    )
    ^
  File "/home/conqueror/PycharmProjects/PythonProject/.venv/lib/python3.13/site-packages/httpx/_client.py", line 1540, in request
    return await self.send(request, auth=auth, follow_redirects=follow_redirects)
           ^^^^^^^^^^^^^^^^^^^^^^^^^^^^^^^^^^^^^^^^^^^^^^^^^^^^^^^^^^^^^^^^^^^^^^
  File "/home/conqueror/PycharmProjects/PythonProject/.venv/lib/python3.13/site-packages/httpx/_client.py", line 1629, in send
    response = await self._send_handling_auth(
               ^^^^^^^^^^^^^^^^^^^^^^^^^^^^^^^
    ...<4 lines>...
    )
    ^
  File "/home/conqueror/PycharmProjects/PythonProject/.venv/lib/python3.13/site-packages/httpx/_client.py", line 1657, in _send_handling_auth
    response = await self._send_handling_redirects(
               ^^^^^^^^^^^^^^^^^^^^^^^^^^^^^^^^^^^^
    ...<3 lines>...
    )
    ^
  File "/home/conqueror/PycharmProjects/PythonProject/.venv/lib/python3.13/site-packages/httpx/_client.py", line 1694, in _send_handling_redirects
    response = await self._send_single_request(request)
               ^^^^^^^^^^^^^^^^^^^^^^^^^^^^^^^^^^^^^^^^
  File "/home/conqueror/PycharmProjects/PythonProject/.venv/lib/python3.13/site-packages/httpx/_client.py", line 1730, in _send_single_request
    response = await transport.handle_async_request(request)
               ^^^^^^^^^^^^^^^^^^^^^^^^^^^^^^^^^^^^^^^^^^^^^
  File "/home/conqueror/PycharmProjects/PythonProject/.venv/lib/python3.13/site-packages/httpx/_transports/default.py", line 393, in handle_async_request
    with map_httpcore_exceptions():
         ~~~~~~~~~~~~~~~~~~~~~~~^^
  File "/usr/lib/python3.13/contextlib.py", line 162, in __exit__
    self.gen.throw(value)
    ~~~~~~~~~~~~~~^^^^^^^
  File "/home/conqueror/PycharmProjects/PythonProject/.venv/lib/python3.13/site-packages/httpx/_transports/default.py", line 118, in map_httpcore_exceptions
    raise mapped_exc(message) from exc
httpx.ConnectTimeout

The above exception was the direct cause of the following exception:

Traceback (most recent call last):
  File "/home/conqueror/PycharmProjects/PythonProject/.venv/lib/python3.13/site-packages/telegram/ext/_updater.py", line 399, in _get_updates_cleanup
    await self.bot.get_updates(
    ...<4 lines>...
    )
  File "/home/conqueror/PycharmProjects/PythonProject/.venv/lib/python3.13/site-packages/telegram/ext/_extbot.py", line 670, in get_updates
    updates = await super().get_updates(
              ^^^^^^^^^^^^^^^^^^^^^^^^^^
    ...<9 lines>...
    )
    ^
  File "/home/conqueror/PycharmProjects/PythonProject/.venv/lib/python3.13/site-packages/telegram/_bot.py", line 4611, in get_updates
    await self._post(
    ^^^^^^^^^^^^^^^^^
    ...<7 lines>...
    ),
    ^
  File "/home/conqueror/PycharmProjects/PythonProject/.venv/lib/python3.13/site-packages/telegram/_bot.py", line 698, in _post
    return await self._do_post(
           ^^^^^^^^^^^^^^^^^^^^
    ...<6 lines>...
    )
    ^
  File "/home/conqueror/PycharmProjects/PythonProject/.venv/lib/python3.13/site-packages/telegram/ext/_extbot.py", line 370, in _do_post
    return await super()._do_post(
           ^^^^^^^^^^^^^^^^^^^^^^^
    ...<6 lines>...
    )
    ^
  File "/home/conqueror/PycharmProjects/PythonProject/.venv/lib/python3.13/site-packages/telegram/_bot.py", line 727, in _do_post
    result = await request.post(
             ^^^^^^^^^^^^^^^^^^^
    ...<6 lines>...
    )
    ^
  File "/home/conqueror/PycharmProjects/PythonProject/.venv/lib/python3.13/site-packages/telegram/request/_baserequest.py", line 197, in post
    result = await self._request_wrapper(
             ^^^^^^^^^^^^^^^^^^^^^^^^^^^^
    ...<7 lines>...
    )
    ^
  File "/home/conqueror/PycharmProjects/PythonProject/.venv/lib/python3.13/site-packages/telegram/request/_baserequest.py", line 304, in _request_wrapper
    code, payload = await self.do_request(
                    ^^^^^^^^^^^^^^^^^^^^^^
    ...<7 lines>...
    )
    ^
  File "/home/conqueror/PycharmProjects/PythonProject/.venv/lib/python3.13/site-packages/telegram/request/_httpxrequest.py", line 290, in do_request
    raise TimedOut from err
telegram.error.TimedOut: Timed out
2025-07-27 11:08:54,650 - telegram.ext.Application - INFO - Application is stopping. This might take a moment.
2025-07-27 11:08:54,651 - telegram.ext.Application - INFO - Application.stop() complete
2025-07-27 11:54:37,137 - telegram.ext.Application - INFO - Application started
2025-07-27 11:54:53,415 - root - INFO - User (7317705516) in private: 'hello'
2025-07-27 11:54:53,416 - root - INFO - Bot response: {response}
2025-07-27 11:55:46,971 - root - INFO - User (7317705516) in private: 'hello'
2025-07-27 11:55:46,971 - root - INFO - Bot response: {response}
2025-07-27 11:59:03,795 - telegram.ext.Updater - ERROR - Error while calling `get_updates` one more time to mark all fetched updates as read: %s. Suppressing error to ensure graceful shutdown. When polling for updates is restarted, updates may be fetched again. Please adjust timeouts via `ApplicationBuilder` or the parameter `get_updates_request` of `Bot`.
Traceback (most recent call last):
  File "/home/conqueror/PycharmProjects/PythonProject/.venv/lib/python3.13/site-packages/httpx/_transports/default.py", line 101, in map_httpcore_exceptions
    yield
  File "/home/conqueror/PycharmProjects/PythonProject/.venv/lib/python3.13/site-packages/httpx/_transports/default.py", line 394, in handle_async_request
    resp = await self._pool.handle_async_request(req)
           ^^^^^^^^^^^^^^^^^^^^^^^^^^^^^^^^^^^^^^^^^^
  File "/home/conqueror/PycharmProjects/PythonProject/.venv/lib/python3.13/site-packages/httpcore/_async/connection_pool.py", line 256, in handle_async_request
    raise exc from None
  File "/home/conqueror/PycharmProjects/PythonProject/.venv/lib/python3.13/site-packages/httpcore/_async/connection_pool.py", line 236, in handle_async_request
    response = await connection.handle_async_request(
               ^^^^^^^^^^^^^^^^^^^^^^^^^^^^^^^^^^^^^^
        pool_request.request
        ^^^^^^^^^^^^^^^^^^^^
    )
    ^
  File "/home/conqueror/PycharmProjects/PythonProject/.venv/lib/python3.13/site-packages/httpcore/_async/connection.py", line 101, in handle_async_request
    raise exc
  File "/home/conqueror/PycharmProjects/PythonProject/.venv/lib/python3.13/site-packages/httpcore/_async/connection.py", line 78, in handle_async_request
    stream = await self._connect(request)
             ^^^^^^^^^^^^^^^^^^^^^^^^^^^^
  File "/home/conqueror/PycharmProjects/PythonProject/.venv/lib/python3.13/site-packages/httpcore/_async/connection.py", line 124, in _connect
    stream = await self._network_backend.connect_tcp(**kwargs)
             ^^^^^^^^^^^^^^^^^^^^^^^^^^^^^^^^^^^^^^^^^^^^^^^^^
  File "/home/conqueror/PycharmProjects/PythonProject/.venv/lib/python3.13/site-packages/httpcore/_backends/auto.py", line 31, in connect_tcp
    return await self._backend.connect_tcp(
           ^^^^^^^^^^^^^^^^^^^^^^^^^^^^^^^^
    ...<5 lines>...
    )
    ^
  File "/home/conqueror/PycharmProjects/PythonProject/.venv/lib/python3.13/site-packages/httpcore/_backends/anyio.py", line 113, in connect_tcp
    with map_exceptions(exc_map):
         ~~~~~~~~~~~~~~^^^^^^^^^
  File "/usr/lib/python3.13/contextlib.py", line 162, in __exit__
    self.gen.throw(value)
    ~~~~~~~~~~~~~~^^^^^^^
  File "/home/conqueror/PycharmProjects/PythonProject/.venv/lib/python3.13/site-packages/httpcore/_exceptions.py", line 14, in map_exceptions
    raise to_exc(exc) from exc
httpcore.ConnectTimeout

The above exception was the direct cause of the following exception:

Traceback (most recent call last):
  File "/home/conqueror/PycharmProjects/PythonProject/.venv/lib/python3.13/site-packages/telegram/request/_httpxrequest.py", line 273, in do_request
    res = await self._client.request(
          ^^^^^^^^^^^^^^^^^^^^^^^^^^^
    ...<6 lines>...
    )
    ^
  File "/home/conqueror/PycharmProjects/PythonProject/.venv/lib/python3.13/site-packages/httpx/_client.py", line 1540, in request
    return await self.send(request, auth=auth, follow_redirects=follow_redirects)
           ^^^^^^^^^^^^^^^^^^^^^^^^^^^^^^^^^^^^^^^^^^^^^^^^^^^^^^^^^^^^^^^^^^^^^^
  File "/home/conqueror/PycharmProjects/PythonProject/.venv/lib/python3.13/site-packages/httpx/_client.py", line 1629, in send
    response = await self._send_handling_auth(
               ^^^^^^^^^^^^^^^^^^^^^^^^^^^^^^^
    ...<4 lines>...
    )
    ^
  File "/home/conqueror/PycharmProjects/PythonProject/.venv/lib/python3.13/site-packages/httpx/_client.py", line 1657, in _send_handling_auth
    response = await self._send_handling_redirects(
               ^^^^^^^^^^^^^^^^^^^^^^^^^^^^^^^^^^^^
    ...<3 lines>...
    )
    ^
  File "/home/conqueror/PycharmProjects/PythonProject/.venv/lib/python3.13/site-packages/httpx/_client.py", line 1694, in _send_handling_redirects
    response = await self._send_single_request(request)
               ^^^^^^^^^^^^^^^^^^^^^^^^^^^^^^^^^^^^^^^^
  File "/home/conqueror/PycharmProjects/PythonProject/.venv/lib/python3.13/site-packages/httpx/_client.py", line 1730, in _send_single_request
    response = await transport.handle_async_request(request)
               ^^^^^^^^^^^^^^^^^^^^^^^^^^^^^^^^^^^^^^^^^^^^^
  File "/home/conqueror/PycharmProjects/PythonProject/.venv/lib/python3.13/site-packages/httpx/_transports/default.py", line 393, in handle_async_request
    with map_httpcore_exceptions():
         ~~~~~~~~~~~~~~~~~~~~~~~^^
  File "/usr/lib/python3.13/contextlib.py", line 162, in __exit__
    self.gen.throw(value)
    ~~~~~~~~~~~~~~^^^^^^^
  File "/home/conqueror/PycharmProjects/PythonProject/.venv/lib/python3.13/site-packages/httpx/_transports/default.py", line 118, in map_httpcore_exceptions
    raise mapped_exc(message) from exc
httpx.ConnectTimeout

The above exception was the direct cause of the following exception:

Traceback (most recent call last):
  File "/home/conqueror/PycharmProjects/PythonProject/.venv/lib/python3.13/site-packages/telegram/ext/_updater.py", line 399, in _get_updates_cleanup
    await self.bot.get_updates(
    ...<4 lines>...
    )
  File "/home/conqueror/PycharmProjects/PythonProject/.venv/lib/python3.13/site-packages/telegram/ext/_extbot.py", line 670, in get_updates
    updates = await super().get_updates(
              ^^^^^^^^^^^^^^^^^^^^^^^^^^
    ...<9 lines>...
    )
    ^
  File "/home/conqueror/PycharmProjects/PythonProject/.venv/lib/python3.13/site-packages/telegram/_bot.py", line 4611, in get_updates
    await self._post(
    ^^^^^^^^^^^^^^^^^
    ...<7 lines>...
    ),
    ^
  File "/home/conqueror/PycharmProjects/PythonProject/.venv/lib/python3.13/site-packages/telegram/_bot.py", line 698, in _post
    return await self._do_post(
           ^^^^^^^^^^^^^^^^^^^^
    ...<6 lines>...
    )
    ^
  File "/home/conqueror/PycharmProjects/PythonProject/.venv/lib/python3.13/site-packages/telegram/ext/_extbot.py", line 370, in _do_post
    return await super()._do_post(
           ^^^^^^^^^^^^^^^^^^^^^^^
    ...<6 lines>...
    )
    ^
  File "/home/conqueror/PycharmProjects/PythonProject/.venv/lib/python3.13/site-packages/telegram/_bot.py", line 727, in _do_post
    result = await request.post(
             ^^^^^^^^^^^^^^^^^^^
    ...<6 lines>...
    )
    ^
  File "/home/conqueror/PycharmProjects/PythonProject/.venv/lib/python3.13/site-packages/telegram/request/_baserequest.py", line 197, in post
    result = await self._request_wrapper(
             ^^^^^^^^^^^^^^^^^^^^^^^^^^^^
    ...<7 lines>...
    )
    ^
  File "/home/conqueror/PycharmProjects/PythonProject/.venv/lib/python3.13/site-packages/telegram/request/_baserequest.py", line 304, in _request_wrapper
    code, payload = await self.do_request(
                    ^^^^^^^^^^^^^^^^^^^^^^
    ...<7 lines>...
    )
    ^
  File "/home/conqueror/PycharmProjects/PythonProject/.venv/lib/python3.13/site-packages/telegram/request/_httpxrequest.py", line 290, in do_request
    raise TimedOut from err
telegram.error.TimedOut: Timed out
2025-07-27 11:59:03,809 - telegram.ext.Application - INFO - Application is stopping. This might take a moment.
2025-07-27 11:59:03,810 - telegram.ext.Application - INFO - Application.stop() complete
2025-07-27 11:59:16,991 - telegram.ext.Application - INFO - Application started
2025-07-27 11:59:51,193 - root - INFO - User (7317705516) in private: 'hello'
2025-07-27 11:59:51,193 - root - INFO - Bot response: Hey there!
2025-07-27 12:03:43,185 - root - ERROR - Update Update(message=Message(channel_chat_created=False, chat=Chat(first_name='Onyi', id=7317705516, last_name='Kachi 🦴🐾', type=<ChatType.PRIVATE>, username='GeorgeTero'), date=datetime.datetime(2025, 7, 27, 16, 3, 38, tzinfo=datetime.timezone.utc), delete_chat_photo=False, entities=(MessageEntity(length=6, offset=0, type=<MessageEntityType.BOT_COMMAND>),), from_user=User(first_name='Onyi', id=7317705516, is_bot=False, language_code='en', last_name='Kachi 🦴🐾', username='GeorgeTero'), group_chat_created=False, message_id=111, supergroup_chat_created=False, text='/start'), update_id=678871834) caused error Timed out
2025-07-27 12:03:45,994 - root - INFO - User (7317705516) in private: 'hello'
2025-07-27 12:03:45,994 - root - INFO - Bot response: Hey there!
2025-07-27 12:03:56,813 - telegram.ext.Application - INFO - Application is stopping. This might take a moment.
2025-07-27 12:03:56,813 - telegram.ext.Application - INFO - Application.stop() complete
